[2025-08-13 08:02:53] Traceback (most recent call last):
  File "C:\laragon\www\siger-lampung\scrapper\dtsen-scraper.py", line 2, in <module>
    from bs4 import BeautifulSoup
ModuleNotFoundError: No module named 'bs4'

[2025-08-13 08:08:08] Traceback (most recent call last):
  File "C:\laragon\www\siger-lampung\scrapper\dtsen-scraper.py", line 909, in <module>
    main()
    ~~~~^^
  File "C:\laragon\www\siger-lampung\scrapper\dtsen-scraper.py", line 903, in main
    print(f"\u2705 {len(df_final)} berita berhasil diproses & dimasukkan ke DB.")
    ~~~~~^^^^^^^^^^^^^^^^^^^^^^^^^^^^^^^^^^^^^^^^^^^^^^^^^^^^^^^^^^^^^^^^^^^^
  File "C:\Python313\Lib\encodings\cp1252.py", line 19, in encode
    return codecs.charmap_encode(input,self.errors,encoding_table)[0]
           ~~~~~~~~~~~~~~~~~~~~~^^^^^^^^^^^^^^^^^^^^^^^^^^^^^^^^^^
UnicodeEncodeError: 'charmap' codec can't encode character '\u2705' in position 0: character maps to <undefined>

[2025-08-13 08:11:54] Traceback (most recent call last):
  File "C:\Users\M.S.I\AppData\Roaming\Python\Python313\site-packages\urllib3\connectionpool.py", line 534, in _make_request
    response = conn.getresponse()
  File "C:\Users\M.S.I\AppData\Roaming\Python\Python313\site-packages\urllib3\connection.py", line 565, in getresponse
    httplib_response = super().getresponse()
  File "C:\Python313\Lib\http\client.py", line 1430, in getresponse
    response.begin()
    ~~~~~~~~~~~~~~^^
  File "C:\Python313\Lib\http\client.py", line 331, in begin
    version, status, reason = self._read_status()
                              ~~~~~~~~~~~~~~~~~^^
  File "C:\Python313\Lib\http\client.py", line 292, in _read_status
    line = str(self.fp.readline(_MAXLINE + 1), "iso-8859-1")
               ~~~~~~~~~~~~~~~~^^^^^^^^^^^^^^
  File "C:\Python313\Lib\socket.py", line 719, in readinto
    return self._sock.recv_into(b)
           ~~~~~~~~~~~~~~~~~~~~^^^
  File "C:\Python313\Lib\ssl.py", line 1304, in recv_into
    return self.read(nbytes, buffer)
           ~~~~~~~~~^^^^^^^^^^^^^^^^
  File "C:\Python313\Lib\ssl.py", line 1138, in read
    return self._sslobj.read(len, buffer)
           ~~~~~~~~~~~~~~~~~^^^^^^^^^^^^^
TimeoutError: The read operation timed out

The above exception was the direct cause of the following exception:

Traceback (most recent call last):
  File "C:\Users\M.S.I\AppData\Roaming\Python\Python313\site-packages\requests\adapters.py", line 667, in send
    resp = conn.urlopen(
        method=request.method,
    ...<9 lines>...
        chunked=chunked,
    )
  File "C:\Users\M.S.I\AppData\Roaming\Python\Python313\site-packages\urllib3\connectionpool.py", line 841, in urlopen
    retries = retries.increment(
        method, url, error=new_e, _pool=self, _stacktrace=sys.exc_info()[2]
    )
  File "C:\Users\M.S.I\AppData\Roaming\Python\Python313\site-packages\urllib3\util\retry.py", line 474, in increment
    raise reraise(type(error), error, _stacktrace)
          ~~~~~~~^^^^^^^^^^^^^^^^^^^^^^^^^^^^^^^^^
  File "C:\Users\M.S.I\AppData\Roaming\Python\Python313\site-packages\urllib3\util\util.py", line 39, in reraise
    raise value
  File "C:\Users\M.S.I\AppData\Roaming\Python\Python313\site-packages\urllib3\connectionpool.py", line 787, in urlopen
    response = self._make_request(
        conn,
    ...<10 lines>...
        **response_kw,
    )
  File "C:\Users\M.S.I\AppData\Roaming\Python\Python313\site-packages\urllib3\connectionpool.py", line 536, in _make_request
    self._raise_timeout(err=e, url=url, timeout_value=read_timeout)
    ~~~~~~~~~~~~~~~~~~~^^^^^^^^^^^^^^^^^^^^^^^^^^^^^^^^^^^^^^^^^^^^
  File "C:\Users\M.S.I\AppData\Roaming\Python\Python313\site-packages\urllib3\connectionpool.py", line 367, in _raise_timeout
    raise ReadTimeoutError(
        self, url, f"Read timed out. (read timeout={timeout_value})"
    ) from err
urllib3.exceptions.ReadTimeoutError: HTTPSConnectionPool(host='lampost.co', port=443): Read timed out. (read timeout=10)

During handling of the above exception, another exception occurred:

Traceback (most recent call last):
  File "C:\laragon\www\siger-lampung\scrapper\dtsen-scraper.py", line 909, in <module>
    main()
    ~~~~^^
  File "C:\laragon\www\siger-lampung\scrapper\dtsen-scraper.py", line 861, in main
    df_lampungpost = get_search_results_lampungpost(keyword, max_pages)
  File "C:\laragon\www\siger-lampung\scrapper\dtsen-scraper.py", line 193, in get_search_results_lampungpost
    response = requests.get(url, timeout=10)
  File "C:\Users\M.S.I\AppData\Roaming\Python\Python313\site-packages\requests\api.py", line 73, in get
    return request("get", url, params=params, **kwargs)
  File "C:\Users\M.S.I\AppData\Roaming\Python\Python313\site-packages\requests\api.py", line 59, in request
    return session.request(method=method, url=url, **kwargs)
           ~~~~~~~~~~~~~~~^^^^^^^^^^^^^^^^^^^^^^^^^^^^^^^^^^
  File "C:\Users\M.S.I\AppData\Roaming\Python\Python313\site-packages\requests\sessions.py", line 589, in request
    resp = self.send(prep, **send_kwargs)
  File "C:\Users\M.S.I\AppData\Roaming\Python\Python313\site-packages\requests\sessions.py", line 703, in send
    r = adapter.send(request, **kwargs)
  File "C:\Users\M.S.I\AppData\Roaming\Python\Python313\site-packages\requests\adapters.py", line 713, in send
    raise ReadTimeout(e, request=request)
requests.exceptions.ReadTimeout: HTTPSConnectionPool(host='lampost.co', port=443): Read timed out. (read timeout=10)

[2025-08-14 08:18:58] Traceback (most recent call last):
  File "C:\Users\M.S.I\AppData\Roaming\Python\Python313\site-packages\urllib3\connectionpool.py", line 787, in urlopen
    response = self._make_request(
        conn,
    ...<10 lines>...
        **response_kw,
    )
  File "C:\Users\M.S.I\AppData\Roaming\Python\Python313\site-packages\urllib3\connectionpool.py", line 488, in _make_request
    raise new_e
  File "C:\Users\M.S.I\AppData\Roaming\Python\Python313\site-packages\urllib3\connectionpool.py", line 464, in _make_request
    self._validate_conn(conn)
    ~~~~~~~~~~~~~~~~~~~^^^^^^
  File "C:\Users\M.S.I\AppData\Roaming\Python\Python313\site-packages\urllib3\connectionpool.py", line 1093, in _validate_conn
    conn.connect()
    ~~~~~~~~~~~~^^
  File "C:\Users\M.S.I\AppData\Roaming\Python\Python313\site-packages\urllib3\connection.py", line 790, in connect
    sock_and_verified = _ssl_wrap_socket_and_match_hostname(
        sock=sock,
    ...<14 lines>...
        assert_fingerprint=self.assert_fingerprint,
    )
  File "C:\Users\M.S.I\AppData\Roaming\Python\Python313\site-packages\urllib3\connection.py", line 969, in _ssl_wrap_socket_and_match_hostname
    ssl_sock = ssl_wrap_socket(
        sock=sock,
    ...<8 lines>...
        tls_in_tls=tls_in_tls,
    )
  File "C:\Users\M.S.I\AppData\Roaming\Python\Python313\site-packages\urllib3\util\ssl_.py", line 480, in ssl_wrap_socket
    ssl_sock = _ssl_wrap_socket_impl(sock, context, tls_in_tls, server_hostname)
  File "C:\Users\M.S.I\AppData\Roaming\Python\Python313\site-packages\urllib3\util\ssl_.py", line 524, in _ssl_wrap_socket_impl
    return ssl_context.wrap_socket(sock, server_hostname=server_hostname)
           ~~~~~~~~~~~~~~~~~~~~~~~^^^^^^^^^^^^^^^^^^^^^^^^^^^^^^^^^^^^^^^
  File "C:\Python313\Lib\ssl.py", line 455, in wrap_socket
    return self.sslsocket_class._create(
           ~~~~~~~~~~~~~~~~~~~~~~~~~~~~^
        sock=sock,
        ^^^^^^^^^^
    ...<5 lines>...
        session=session
        ^^^^^^^^^^^^^^^
    )
    ^
  File "C:\Python313\Lib\ssl.py", line 1076, in _create
    self.do_handshake()
    ~~~~~~~~~~~~~~~~~^^
  File "C:\Python313\Lib\ssl.py", line 1372, in do_handshake
    self._sslobj.do_handshake()
    ~~~~~~~~~~~~~~~~~~~~~~~~~^^
ConnectionAbortedError: [WinError 10053] An established connection was aborted by the software in your host machine

During handling of the above exception, another exception occurred:

Traceback (most recent call last):
  File "C:\Users\M.S.I\AppData\Roaming\Python\Python313\site-packages\requests\adapters.py", line 667, in send
    resp = conn.urlopen(
        method=request.method,
    ...<9 lines>...
        chunked=chunked,
    )
  File "C:\Users\M.S.I\AppData\Roaming\Python\Python313\site-packages\urllib3\connectionpool.py", line 841, in urlopen
    retries = retries.increment(
        method, url, error=new_e, _pool=self, _stacktrace=sys.exc_info()[2]
    )
  File "C:\Users\M.S.I\AppData\Roaming\Python\Python313\site-packages\urllib3\util\retry.py", line 474, in increment
    raise reraise(type(error), error, _stacktrace)
          ~~~~~~~^^^^^^^^^^^^^^^^^^^^^^^^^^^^^^^^^
  File "C:\Users\M.S.I\AppData\Roaming\Python\Python313\site-packages\urllib3\util\util.py", line 38, in reraise
    raise value.with_traceback(tb)
  File "C:\Users\M.S.I\AppData\Roaming\Python\Python313\site-packages\urllib3\connectionpool.py", line 787, in urlopen
    response = self._make_request(
        conn,
    ...<10 lines>...
        **response_kw,
    )
  File "C:\Users\M.S.I\AppData\Roaming\Python\Python313\site-packages\urllib3\connectionpool.py", line 488, in _make_request
    raise new_e
  File "C:\Users\M.S.I\AppData\Roaming\Python\Python313\site-packages\urllib3\connectionpool.py", line 464, in _make_request
    self._validate_conn(conn)
    ~~~~~~~~~~~~~~~~~~~^^^^^^
  File "C:\Users\M.S.I\AppData\Roaming\Python\Python313\site-packages\urllib3\connectionpool.py", line 1093, in _validate_conn
    conn.connect()
    ~~~~~~~~~~~~^^
  File "C:\Users\M.S.I\AppData\Roaming\Python\Python313\site-packages\urllib3\connection.py", line 790, in connect
    sock_and_verified = _ssl_wrap_socket_and_match_hostname(
        sock=sock,
    ...<14 lines>...
        assert_fingerprint=self.assert_fingerprint,
    )
  File "C:\Users\M.S.I\AppData\Roaming\Python\Python313\site-packages\urllib3\connection.py", line 969, in _ssl_wrap_socket_and_match_hostname
    ssl_sock = ssl_wrap_socket(
        sock=sock,
    ...<8 lines>...
        tls_in_tls=tls_in_tls,
    )
  File "C:\Users\M.S.I\AppData\Roaming\Python\Python313\site-packages\urllib3\util\ssl_.py", line 480, in ssl_wrap_socket
    ssl_sock = _ssl_wrap_socket_impl(sock, context, tls_in_tls, server_hostname)
  File "C:\Users\M.S.I\AppData\Roaming\Python\Python313\site-packages\urllib3\util\ssl_.py", line 524, in _ssl_wrap_socket_impl
    return ssl_context.wrap_socket(sock, server_hostname=server_hostname)
           ~~~~~~~~~~~~~~~~~~~~~~~^^^^^^^^^^^^^^^^^^^^^^^^^^^^^^^^^^^^^^^
  File "C:\Python313\Lib\ssl.py", line 455, in wrap_socket
    return self.sslsocket_class._create(
           ~~~~~~~~~~~~~~~~~~~~~~~~~~~~^
        sock=sock,
        ^^^^^^^^^^
    ...<5 lines>...
        session=session
        ^^^^^^^^^^^^^^^
    )
    ^
  File "C:\Python313\Lib\ssl.py", line 1076, in _create
    self.do_handshake()
    ~~~~~~~~~~~~~~~~~^^
  File "C:\Python313\Lib\ssl.py", line 1372, in do_handshake
    self._sslobj.do_handshake()
    ~~~~~~~~~~~~~~~~~~~~~~~~~^^
urllib3.exceptions.ProtocolError: ('Connection aborted.', ConnectionAbortedError(10053, 'An established connection was aborted by the software in your host machine', None, 10053, None))

During handling of the above exception, another exception occurred:

Traceback (most recent call last):
  File "C:\laragon\www\siger-lampung\scrapper\dtsen-scraper.py", line 894, in <module>
    main()
    ~~~~^^
  File "C:\laragon\www\siger-lampung\scrapper\dtsen-scraper.py", line 851, in main
    df_serambilampung = get_search_results_serambilampung(keyword, max_pages, timeout)
  File "C:\laragon\www\siger-lampung\scrapper\dtsen-scraper.py", line 483, in get_search_results_serambilampung
    response = requests.get(url, timeout)
  File "C:\Users\M.S.I\AppData\Roaming\Python\Python313\site-packages\requests\api.py", line 73, in get
    return request("get", url, params=params, **kwargs)
  File "C:\Users\M.S.I\AppData\Roaming\Python\Python313\site-packages\requests\api.py", line 59, in request
    return session.request(method=method, url=url, **kwargs)
           ~~~~~~~~~~~~~~~^^^^^^^^^^^^^^^^^^^^^^^^^^^^^^^^^^
  File "C:\Users\M.S.I\AppData\Roaming\Python\Python313\site-packages\requests\sessions.py", line 589, in request
    resp = self.send(prep, **send_kwargs)
  File "C:\Users\M.S.I\AppData\Roaming\Python\Python313\site-packages\requests\sessions.py", line 703, in send
    r = adapter.send(request, **kwargs)
  File "C:\Users\M.S.I\AppData\Roaming\Python\Python313\site-packages\requests\adapters.py", line 682, in send
    raise ConnectionError(err, request=request)
requests.exceptions.ConnectionError: ('Connection aborted.', ConnectionAbortedError(10053, 'An established connection was aborted by the software in your host machine', None, 10053, None))

